<?xml version="1.0"?>
<robot xmlns:xacro="http://ros.org/wiki/xacro">
    <xacro:include filename="$(find servo_description)/urdf/servo.transmission.xacro" />
    <xacro:include filename="$(find servo_description)/urdf/servo.gazebo.xacro" />

    <!-- Inertia parameters -->
    <xacro:property name="base_mass" value="4.0" />  <!-- This mass might be incorrect -->
    <xacro:property name="a1_mass" value="3.7000" />
    <xacro:property name="a2_mass" value="8.3930" />
    <xacro:property name="a3_mass" value="2.2750" />
    <xacro:property name="a4_mass" value="1.2190" />
    <xacro:property name="a5_mass" value="1.2190" />
    <xacro:property name="a6_mass" value="0.1879" />

    <!-- Kinematic model -->
    <!-- Properties from urcontrol.conf -->
    <!--
        DH for UR5:
        a = [0.00000, -0.42500, -0.39225,  0.00000,  0.00000,  0.0000]
        d = [0.089159,  0.00000,  0.00000,  0.10915,  0.09465,  0.0823]
        alpha = [ 1.570796327, 0, 0, 1.570796327, -1.570796327, 0 ]
        q_home_offset = [0, -1.570796327, 0, -1.570796327, 0, 0]
        joint_direction = [-1, -1, 1, 1, 1, 1]
        mass = [3.7000, 8.3930, 2.2750, 1.2190, 1.2190, 0.1879]
        center_of_mass = [ [0, -0.02561, 0.00193], [0.2125, 0, 0.11336], [0.11993, 0.0, 0.0265], [0, -0.0018, 0.01634], [0, 0.0018,0.01634], [0, 0, -0.001159] ]
    -->

    <xacro:property name="servo_d1" value="0.089159" />
    <xacro:property name="servo_a2" value="-0.42500" />
    <xacro:property name="servo_a3" value="-0.39225" />
    <xacro:property name="servo_d4" value="0.10915" />
    <xacro:property name="servo_d5" value="0.09465" />
    <xacro:property name="servo_d6" value="0.0823" />

    <!-- Arbitrary offsets for shoulder/elbow joints -->
    <xacro:property name="shoulder_offset" value="0.13585" />  <!-- measured from model -->
    <xacro:property name="elbow_offset" value="-0.1197" /> <!-- measured from model -->

    <!-- link lengths used in model -->
    <xacro:property name="a1_height" value="${servo_d1}" />
    <xacro:property name="a2_length" value="${-servo_a2}" />
    <xacro:property name="a3_length" value="${-servo_a3}" />
    <xacro:property name="a4_length" value="${servo_d4}" />
    <xacro:property name="a5_length" value="${servo_d5}" />
    <xacro:property name="a6_length" value="${servo_d6}" />

    <!--property name="shoulder_height" value="0.089159" /-->
    <!--property name="shoulder_offset" value="0.13585" /-->  <!-- shoulder_offset - elbow_offset + wrist_1_length = 0.10915 -->
    <!--property name="upper_arm_length" value="0.42500" /-->
    <!--property name="elbow_offset" value="0.1197" /-->       <!-- CAD measured -->
    <!--property name="forearm_length" value="0.39225" /-->
    <!--property name="wrist_1_length" value="0.093" /-->     <!-- CAD measured -->
    <!--property name="wrist_2_length" value="0.09465" /-->   <!-- In CAD this distance is 0.930, but in the spec it is 0.09465 -->
    <!--property name="wrist_3_length" value="0.0823" /-->

    <xacro:property name="shoulder_radius" value="0.060" />   <!-- manually measured -->
    <xacro:property name="upper_arm_radius" value="0.054" />  <!-- manually measured -->
    <xacro:property name="elbow_radius" value="0.060" />      <!-- manually measured -->
    <xacro:property name="forearm_radius" value="0.040" />    <!-- manually measured -->
    <xacro:property name="wrist_radius" value="0.045" />      <!-- manually measured -->

    <xacro:macro name="cylinder_inertial" params="radius length mass *origin">
        <inertial>
            <mass value="${mass}" />
            <xacro:insert_block name="origin" />
            <inertia
                ixx="${0.0833333 * mass * (3 * radius * radius + length * length)}" ixy="0.0" ixz="0.0"
                iyy="${0.0833333 * mass * (3 * radius * radius + length * length)}" iyz="0.0"
                izz="${0.5 * mass * radius * radius}"
            />
        </inertial>
    </xacro:macro>

    <xacro:macro name="null_inertial" params="radius length mass *origin">
        <inertial>
            <mass value="${mass}" />
            <xacro:insert_block name="origin" />
            <inertia
                ixx="0" ixy="0" ixz="0"
                iyy="0" iyz="0"
                izz="0"
            />
        </inertial>
    </xacro:macro>

    <xacro:macro name="servo_robot" params="prefix joint_limited
        a1_lower_limit:=${-pi}    a1_upper_limit:=${pi}
        a2_lower_limit:=${-pi}    a2_upper_limit:=${pi}
        a3_lower_limit:=${-pi}    a3_upper_limit:=${pi}
        a4_lower_limit:=${-pi}    a4_upper_limit:=${pi}
        a5_lower_limit:=${-pi}    a5_upper_limit:=${pi}
        a6_lower_limit:=${-pi}    a6_upper_limit:=${pi}">

        <link name="${prefix}base_link" >
            <visual>
                <geometry>
                    <mesh filename="package://servo_description/meshes/base_link.stl" />
                </geometry>
                <material name="Black">
                    <color rgba="0.7 0.7 0.7 1.0"/>
                </material>
            </visual>
            <collision>
                <geometry>
                    <mesh filename="package://servo_description/meshes/base_link.stl" />
                </geometry>
            </collision>
            <xacro:null_inertial radius="0.06" length="0.05" mass="${base_mass}">
                <origin xyz="0.0 0.0 0.0" rpy="0 0 0" />
            </xacro:null_inertial>
        </link>

        <joint name="${prefix}a1_joint" type="revolute">
            <parent link="${prefix}base_link" />
            <child link = "${prefix}a1_link" />
            <origin xyz="0 0 0" rpy="-0.18123 -1.5708 0.18123" />
            <axis xyz="1 0 0" />
            <xacro:unless value="${joint_limited}">
                <limit lower="${-2.0 * pi}" upper="${2.0 * pi}" effort="150.0" velocity="3.15"/>
            </xacro:unless>
            <xacro:if value="${joint_limited}">
                <limit lower="${a1_lower_limit}" upper="${a1_upper_limit}" effort="150.0" velocity="3.15"/>
            </xacro:if>
            <dynamics damping="0.0" friction="0.0"/>
        </joint>

        <link name="${prefix}a1_link">
            <visual>
                <geometry>
                    <mesh filename="package://servo_description/meshes/a1.stl" />
                </geometry>
                <material name="LightGrey">
                    <color rgba="0.1 0.1 0.1 1.0"/>
                </material>
            </visual>
            <collision>
                <geometry>
                    <mesh filename="package://servo_description/meshes/a1.stl" />
                </geometry>
            </collision>
            <xacro:null_inertial radius="0.06" length="0.15" mass="${a1_mass}">
                <origin xyz="0.0 0.0 0.0" rpy="0 0 0" />
            </xacro:null_inertial>
        </link>

        <joint name="${prefix}a2_joint" type="revolute">
            <parent link="${prefix}a1_link" />
            <child link = "${prefix}a2_link" />
            <origin xyz="0.23 0.023553 -0.087899" rpy="0 1.5708 0" />
            <axis xyz="0.96593 0.25882 0" />
            <xacro:unless value="${joint_limited}">
                <limit lower="${-2.0 * pi}" upper="${2.0 * pi}" effort="150.0" velocity="3.15"/>
            </xacro:unless>
            <xacro:if value="${joint_limited}">
                <limit lower="${a2_lower_limit}" upper="${a2_upper_limit}" effort="150.0" velocity="3.15"/>
            </xacro:if>
            <dynamics damping="0.0" friction="0.0"/>
        </joint>

        <link name="${prefix}a2_link">
            <visual>
                <geometry>
                    <mesh filename="package://servo_description/meshes/a2.stl" />
                </geometry>
                <material name="Black">
                    <color rgba="0.2 0.2 0.2 1.0"/>
                </material>
            </visual>
            <collision>
                <geometry>
                    <mesh filename="package://servo_description/meshes/a2.stl" />
                </geometry>
            </collision>
            <xacro:null_inertial radius="0.06" length="0.56" mass="${a2_mass}">
                <origin xyz="0.0 0.0 0.28" rpy="0 0 0" />
            </xacro:null_inertial>
        </link>

        <joint name="${prefix}a3_joint" type="revolute">
            <parent link="${prefix}a2_link" />
            <child link = "${prefix}a3_link" />
            <origin xyz="-0.027529 -0.0073763 0.25899" rpy="0 0 0" />
            <axis xyz="0.96593 0.25882 0" />
            <xacro:unless value="${joint_limited}">
                <limit lower="${-pi}" upper="${pi}" effort="150.0" velocity="3.15"/>
            </xacro:unless>
            <xacro:if value="${joint_limited}">
                <limit lower="${a3_lower_limit}" upper="${a3_upper_limit}" effort="150.0" velocity="3.15"/>
            </xacro:if>
            <dynamics damping="0.0" friction="0.0"/>
        </joint>

        <link name="${prefix}a3_link">
            <visual>
                <geometry>
                    <mesh filename="package://servo_description/meshes/a3.stl" />
                </geometry>
                <material name="LightGrey">
                    <color rgba="0.3 0.3 0.3 1.0"/>
                </material>
            </visual>
            <collision>
                <geometry>
                    <mesh filename="package://servo_description/meshes/a3.stl" />
                </geometry>
            </collision>
            <xacro:null_inertial radius="0.06" length="0.5" mass="${a3_mass}">
                <origin xyz="0.0 0.0 0.25" rpy="0 0 0" />
            </xacro:null_inertial>
        </link>

        <joint name="${prefix}a4_joint" type="revolute">
            <parent link="${prefix}a3_link" />
            <child link = "${prefix}a4_link" />
            <origin xyz="-0.040569 -0.01087 0.058" rpy="0 0 0" />
            <axis xyz="0 0 1" />
            <xacro:unless value="${joint_limited}">
                <limit lower="${-2.0 * pi}" upper="${2.0 * pi}" effort="28.0" velocity="3.2"/>
            </xacro:unless>
            <xacro:if value="${joint_limited}">
                <limit lower="${a4_lower_limit}" upper="${a4_upper_limit}" effort="28.0" velocity="3.2"/>
            </xacro:if>
            <dynamics damping="0.0" friction="0.0"/>
        </joint>

        <link name="${prefix}a4_link">
            <visual>
                <geometry>
                    <mesh filename="package://servo_description/meshes/a4.stl" />
                </geometry>
                <material name="Green">
                    <color rgba="0.4 0.4 0.4 1.0"/>
                </material>
            </visual>
            <collision>
                <geometry>
                    <mesh filename="package://servo_description/meshes/a4.stl" />
                </geometry>
            </collision>
            <xacro:null_inertial radius="0.6" length="0.12" mass="${a4_mass}">
                <origin xyz="0.0 0.0 0.0" rpy="0 0 0" />
            </xacro:null_inertial>
        </link>

        <joint name="${prefix}a5_joint" type="revolute">
            <parent link="${prefix}a4_link" />
            <child link = "${prefix}a5_link" />
            <origin xyz="0.044433 0.011906 0.21" rpy="0 0 0" />
            <axis xyz="0.96593 0.25882 0" />
            <xacro:unless value="${joint_limited}">
                <limit lower="${-2.0 * pi}" upper="${2.0 * pi}" effort="28.0" velocity="3.2"/>
            </xacro:unless>
            <xacro:if value="${joint_limited}">
                <limit lower="${a5_lower_limit}" upper="${a5_upper_limit}" effort="28.0" velocity="3.2"/>
            </xacro:if>
            <dynamics damping="0.0" friction="0.0"/>
        </joint>

        <link name="${prefix}a5_link">
            <visual>
                <geometry>
                    <mesh filename="package://servo_description/meshes/a5.stl" />
                </geometry>
                <material name="Black">
                    <color rgba="0.5 0.5 0.5 1.0"/>
                </material>
            </visual>
            <collision>
                <geometry>
                    <mesh filename="package://servo_description/meshes/a5.stl" />
                </geometry>
            </collision>
            <xacro:null_inertial radius="0.6" length="0.12" mass="${a5_mass}">
                <origin xyz="0.0 0.0 0.0" rpy="0 0 0" />
            </xacro:null_inertial>
        </link>

        <joint name="${prefix}a6_joint" type="revolute">
            <parent link="${prefix}a5_link" />
            <child link = "${prefix}a6_link" />
            <origin xyz="0.016179 0.0043352 0.0615" rpy="0 0 0" />
            <axis xyz="0 0 1" />
            <xacro:unless value="${joint_limited}">
                <limit lower="${-2.0 * pi}" upper="${2.0 * pi}" effort="28.0" velocity="3.2"/>
            </xacro:unless>
            <xacro:if value="${joint_limited}">
                <limit lower="${a6_lower_limit}" upper="${a6_upper_limit}" effort="28.0" velocity="3.2"/>
            </xacro:if>
            <dynamics damping="0.0" friction="0.0"/>
        </joint>

        <link name="${prefix}a6_link">
            <visual>
                <geometry>
                    <mesh filename="package://servo_description/meshes/a6.stl" />
                </geometry>
                <material name="LightGrey">
                    <color rgba="0.7 0.7 0.7 1.0"/>
                </material>
            </visual>
            <collision>
                <geometry>
                    <mesh filename="package://servo_description/meshes/a6.stl" />
                </geometry>
            </collision>
            <xacro:null_inertial radius="0.6" length="0.12" mass="${a6_mass}">
                <origin xyz="0.0 0.0 0.0" rpy="0 0 0" />
            </xacro:null_inertial>
        </link>

        <joint name="${prefix}ee_fixed_joint" type="fixed">
            <parent link="${prefix}a6_link" />
            <child link = "${prefix}ee_link" />
            <origin xyz="0.0 0.0 0.10" rpy="0.0 0.0 ${pi/2.0}" />
        </joint>

        <link name="${prefix}ee_link">
            <collision>
                <geometry>
                    <box size="0.01 0.01 0.01"/>
                </geometry>
                <origin rpy="0 0 0" xyz="-0.01 0 0"/>
            </collision>
        </link>

        <xacro:servo_arm_transmission prefix="${prefix}" />
        <xacro:servo_arm_gazebo prefix="${prefix}" />

        <!-- ROS base_link to UR 'Base' Coordinates transform -->
        <link name="${prefix}base"/>
        <joint name="${prefix}base_link-base_fixed_joint" type="fixed">
            <!-- NOTE: this rotation is only needed as long as base_link itself is
                 not corrected wrt the real robot (ie: rotated over 180 degrees)
            -->
            <origin xyz="0 0 0" rpy="0 0 ${-pi}"/>
            <parent link="${prefix}base_link"/>
            <child link="${prefix}base"/>
        </joint>

        <!-- Frame coincident with all-zeros TCP on UR controller -->
        <link name="${prefix}tool0"/>
        <joint name="${prefix}a6_link-tool0_fixed_joint" type="fixed">
            <origin xyz="0 ${a6_length} 0" rpy="${pi/-2.0} 0 0"/>
            <parent link="${prefix}a6_link"/>
            <child link="${prefix}tool0"/>
        </joint>

    </xacro:macro>
</robot>
